[2021-04-09 16:05:56,887] [INFO] [root] 
--- Logging error ---
Traceback (most recent call last):
  File "c:\users\1111111\appdata\local\programs\python\python36\lib\logging\handlers.py", line 72, in emit
    self.doRollover()
  File "c:\users\1111111\appdata\local\programs\python\python36\lib\logging\handlers.py", line 396, in doRollover
    self.rotate(self.baseFilename, dfn)
  File "c:\users\1111111\appdata\local\programs\python\python36\lib\logging\handlers.py", line 113, in rotate
    os.rename(source, dest)
PermissionError: [WinError 32] 另一个程序正在使用此文件，进程无法访问。: 'C:\\Users\\1111111\\PycharmProjects\\ApiAutoTest\\logs\\test.log' -> 'C:\\Users\\1111111\\PycharmProjects\\ApiAutoTest\\logs\\test.log.2021-04-09_10-13-10'
Call stack:
  File "<string>", line 1, in <module>
  File "<string>", line 8, in <module>
  File "c:\users\1111111\appdata\local\programs\python\python36\lib\site-packages\execnet\gateway_base.py", line 1554, in serve
    SlaveGateway(io=io, id=id, _startcount=2).serve()
  File "c:\users\1111111\appdata\local\programs\python\python36\lib\site-packages\execnet\gateway_base.py", line 1060, in serve
    self._execpool.integrate_as_primary_thread()
  File "c:\users\1111111\appdata\local\programs\python\python36\lib\site-packages\execnet\gateway_base.py", line 267, in integrate_as_primary_thread
    self._perform_spawn(reply)
  File "c:\users\1111111\appdata\local\programs\python\python36\lib\site-packages\execnet\gateway_base.py", line 285, in _perform_spawn
    reply.run()
  File "c:\users\1111111\appdata\local\programs\python\python36\lib\site-packages\execnet\gateway_base.py", line 220, in run
    self._result = func(*args, **kwargs)
  File "c:\users\1111111\appdata\local\programs\python\python36\lib\site-packages\execnet\gateway_base.py", line 1084, in executetask
    do_exec(co, loc)  # noqa
  File "c:\users\1111111\appdata\local\programs\python\python36\lib\site-packages\xdist\remote.py", line 239, in <module>
    config.hook.pytest_cmdline_main(config=config)
  File "c:\users\1111111\appdata\local\programs\python\python36\lib\site-packages\pluggy\hooks.py", line 286, in __call__
    return self._hookexec(self, self.get_hookimpls(), kwargs)
  File "c:\users\1111111\appdata\local\programs\python\python36\lib\site-packages\pluggy\manager.py", line 93, in _hookexec
    return self._inner_hookexec(hook, methods, kwargs)
  File "c:\users\1111111\appdata\local\programs\python\python36\lib\site-packages\pluggy\manager.py", line 87, in <lambda>
    firstresult=hook.spec.opts.get("firstresult") if hook.spec else False,
  File "c:\users\1111111\appdata\local\programs\python\python36\lib\site-packages\pluggy\callers.py", line 187, in _multicall
    res = hook_impl.function(*args)
  File "c:\users\1111111\appdata\local\programs\python\python36\lib\site-packages\_pytest\main.py", line 316, in pytest_cmdline_main
    return wrap_session(config, _main)
  File "c:\users\1111111\appdata\local\programs\python\python36\lib\site-packages\_pytest\main.py", line 269, in wrap_session
    session.exitstatus = doit(config, session) or 0
  File "c:\users\1111111\appdata\local\programs\python\python36\lib\site-packages\_pytest\main.py", line 323, in _main
    config.hook.pytest_runtestloop(session=session)
  File "c:\users\1111111\appdata\local\programs\python\python36\lib\site-packages\pluggy\hooks.py", line 286, in __call__
    return self._hookexec(self, self.get_hookimpls(), kwargs)
  File "c:\users\1111111\appdata\local\programs\python\python36\lib\site-packages\pluggy\manager.py", line 93, in _hookexec
    return self._inner_hookexec(hook, methods, kwargs)
  File "c:\users\1111111\appdata\local\programs\python\python36\lib\site-packages\pluggy\manager.py", line 87, in <lambda>
    firstresult=hook.spec.opts.get("firstresult") if hook.spec else False,
  File "c:\users\1111111\appdata\local\programs\python\python36\lib\site-packages\pluggy\callers.py", line 187, in _multicall
    res = hook_impl.function(*args)
  File "c:\users\1111111\appdata\local\programs\python\python36\lib\site-packages\xdist\remote.py", line 72, in pytest_runtestloop
    self.run_one_test(torun)
  File "c:\users\1111111\appdata\local\programs\python\python36\lib\site-packages\xdist\remote.py", line 89, in run_one_test
    self.config.hook.pytest_runtest_protocol(item=item, nextitem=nextitem)
  File "c:\users\1111111\appdata\local\programs\python\python36\lib\site-packages\pluggy\hooks.py", line 286, in __call__
    return self._hookexec(self, self.get_hookimpls(), kwargs)
  File "c:\users\1111111\appdata\local\programs\python\python36\lib\site-packages\pluggy\manager.py", line 93, in _hookexec
    return self._inner_hookexec(hook, methods, kwargs)
  File "c:\users\1111111\appdata\local\programs\python\python36\lib\site-packages\pluggy\manager.py", line 87, in <lambda>
    firstresult=hook.spec.opts.get("firstresult") if hook.spec else False,
  File "c:\users\1111111\appdata\local\programs\python\python36\lib\site-packages\pluggy\callers.py", line 187, in _multicall
    res = hook_impl.function(*args)
  File "c:\users\1111111\appdata\local\programs\python\python36\lib\site-packages\_pytest\runner.py", line 109, in pytest_runtest_protocol
    runtestprotocol(item, nextitem=nextitem)
  File "c:\users\1111111\appdata\local\programs\python\python36\lib\site-packages\_pytest\runner.py", line 126, in runtestprotocol
    reports.append(call_and_report(item, "call", log))
  File "c:\users\1111111\appdata\local\programs\python\python36\lib\site-packages\_pytest\runner.py", line 215, in call_and_report
    call = call_runtest_hook(item, when, **kwds)
  File "c:\users\1111111\appdata\local\programs\python\python36\lib\site-packages\_pytest\runner.py", line 255, in call_runtest_hook
    lambda: ihook(item=item, **kwds), when=when, reraise=reraise
  File "c:\users\1111111\appdata\local\programs\python\python36\lib\site-packages\_pytest\runner.py", line 311, in from_call
    result: Optional[TResult] = func()
  File "c:\users\1111111\appdata\local\programs\python\python36\lib\site-packages\_pytest\runner.py", line 255, in <lambda>
    lambda: ihook(item=item, **kwds), when=when, reraise=reraise
  File "c:\users\1111111\appdata\local\programs\python\python36\lib\site-packages\pluggy\hooks.py", line 286, in __call__
    return self._hookexec(self, self.get_hookimpls(), kwargs)
  File "c:\users\1111111\appdata\local\programs\python\python36\lib\site-packages\pluggy\manager.py", line 93, in _hookexec
    return self._inner_hookexec(hook, methods, kwargs)
  File "c:\users\1111111\appdata\local\programs\python\python36\lib\site-packages\pluggy\manager.py", line 87, in <lambda>
    firstresult=hook.spec.opts.get("firstresult") if hook.spec else False,
  File "c:\users\1111111\appdata\local\programs\python\python36\lib\site-packages\pluggy\callers.py", line 187, in _multicall
    res = hook_impl.function(*args)
  File "c:\users\1111111\appdata\local\programs\python\python36\lib\site-packages\_pytest\runner.py", line 162, in pytest_runtest_call
    item.runtest()
  File "c:\users\1111111\appdata\local\programs\python\python36\lib\site-packages\_pytest\python.py", line 1641, in runtest
    self.ihook.pytest_pyfunc_call(pyfuncitem=self)
  File "c:\users\1111111\appdata\local\programs\python\python36\lib\site-packages\pluggy\hooks.py", line 286, in __call__
    return self._hookexec(self, self.get_hookimpls(), kwargs)
  File "c:\users\1111111\appdata\local\programs\python\python36\lib\site-packages\pluggy\manager.py", line 93, in _hookexec
    return self._inner_hookexec(hook, methods, kwargs)
  File "c:\users\1111111\appdata\local\programs\python\python36\lib\site-packages\pluggy\manager.py", line 87, in <lambda>
    firstresult=hook.spec.opts.get("firstresult") if hook.spec else False,
  File "c:\users\1111111\appdata\local\programs\python\python36\lib\site-packages\pluggy\callers.py", line 187, in _multicall
    res = hook_impl.function(*args)
  File "c:\users\1111111\appdata\local\programs\python\python36\lib\site-packages\_pytest\python.py", line 183, in pytest_pyfunc_call
    result = testfunction(**testargs)
  File "C:\Users\1111111\PycharmProjects\ApiAutoTest\script\test_login.py", line 59, in test_correct_login
    logging.info(err)
Message: ''
Arguments: ()
[2021-04-09 16:05:57,909] [INFO] [root] 没有登录进去
assert 'QQ邮箱' == '登录QQ邮箱'
  - 登录QQ邮箱
  ? --
  + QQ邮箱
--- Logging error ---
Traceback (most recent call last):
  File "C:\Users\1111111\PycharmProjects\ApiAutoTest\script\test_login.py", line 62, in test_correct_login
    assert "QQ邮箱" == t1, '没有登录进去'
AssertionError: 没有登录进去
assert 'QQ邮箱' == '登录QQ邮箱'
  - 登录QQ邮箱
  ? --
  + QQ邮箱

During handling of the above exception, another exception occurred:

Traceback (most recent call last):
  File "c:\users\1111111\appdata\local\programs\python\python36\lib\logging\handlers.py", line 72, in emit
    self.doRollover()
  File "c:\users\1111111\appdata\local\programs\python\python36\lib\logging\handlers.py", line 396, in doRollover
    self.rotate(self.baseFilename, dfn)
  File "c:\users\1111111\appdata\local\programs\python\python36\lib\logging\handlers.py", line 113, in rotate
    os.rename(source, dest)
PermissionError: [WinError 32] 另一个程序正在使用此文件，进程无法访问。: 'C:\\Users\\1111111\\PycharmProjects\\ApiAutoTest\\logs\\test.log' -> 'C:\\Users\\1111111\\PycharmProjects\\ApiAutoTest\\logs\\test.log.2021-04-09_10-13-10'
Call stack:
  File "<string>", line 1, in <module>
  File "<string>", line 8, in <module>
  File "c:\users\1111111\appdata\local\programs\python\python36\lib\site-packages\execnet\gateway_base.py", line 1554, in serve
    SlaveGateway(io=io, id=id, _startcount=2).serve()
  File "c:\users\1111111\appdata\local\programs\python\python36\lib\site-packages\execnet\gateway_base.py", line 1060, in serve
    self._execpool.integrate_as_primary_thread()
  File "c:\users\1111111\appdata\local\programs\python\python36\lib\site-packages\execnet\gateway_base.py", line 267, in integrate_as_primary_thread
    self._perform_spawn(reply)
  File "c:\users\1111111\appdata\local\programs\python\python36\lib\site-packages\execnet\gateway_base.py", line 285, in _perform_spawn
    reply.run()
  File "c:\users\1111111\appdata\local\programs\python\python36\lib\site-packages\execnet\gateway_base.py", line 220, in run
    self._result = func(*args, **kwargs)
  File "c:\users\1111111\appdata\local\programs\python\python36\lib\site-packages\execnet\gateway_base.py", line 1084, in executetask
    do_exec(co, loc)  # noqa
  File "c:\users\1111111\appdata\local\programs\python\python36\lib\site-packages\xdist\remote.py", line 239, in <module>
    config.hook.pytest_cmdline_main(config=config)
  File "c:\users\1111111\appdata\local\programs\python\python36\lib\site-packages\pluggy\hooks.py", line 286, in __call__
    return self._hookexec(self, self.get_hookimpls(), kwargs)
  File "c:\users\1111111\appdata\local\programs\python\python36\lib\site-packages\pluggy\manager.py", line 93, in _hookexec
    return self._inner_hookexec(hook, methods, kwargs)
  File "c:\users\1111111\appdata\local\programs\python\python36\lib\site-packages\pluggy\manager.py", line 87, in <lambda>
    firstresult=hook.spec.opts.get("firstresult") if hook.spec else False,
  File "c:\users\1111111\appdata\local\programs\python\python36\lib\site-packages\pluggy\callers.py", line 187, in _multicall
    res = hook_impl.function(*args)
  File "c:\users\1111111\appdata\local\programs\python\python36\lib\site-packages\_pytest\main.py", line 316, in pytest_cmdline_main
    return wrap_session(config, _main)
  File "c:\users\1111111\appdata\local\programs\python\python36\lib\site-packages\_pytest\main.py", line 269, in wrap_session
    session.exitstatus = doit(config, session) or 0
  File "c:\users\1111111\appdata\local\programs\python\python36\lib\site-packages\_pytest\main.py", line 323, in _main
    config.hook.pytest_runtestloop(session=session)
  File "c:\users\1111111\appdata\local\programs\python\python36\lib\site-packages\pluggy\hooks.py", line 286, in __call__
    return self._hookexec(self, self.get_hookimpls(), kwargs)
  File "c:\users\1111111\appdata\local\programs\python\python36\lib\site-packages\pluggy\manager.py", line 93, in _hookexec
    return self._inner_hookexec(hook, methods, kwargs)
  File "c:\users\1111111\appdata\local\programs\python\python36\lib\site-packages\pluggy\manager.py", line 87, in <lambda>
    firstresult=hook.spec.opts.get("firstresult") if hook.spec else False,
  File "c:\users\1111111\appdata\local\programs\python\python36\lib\site-packages\pluggy\callers.py", line 187, in _multicall
    res = hook_impl.function(*args)
  File "c:\users\1111111\appdata\local\programs\python\python36\lib\site-packages\xdist\remote.py", line 72, in pytest_runtestloop
    self.run_one_test(torun)
  File "c:\users\1111111\appdata\local\programs\python\python36\lib\site-packages\xdist\remote.py", line 89, in run_one_test
    self.config.hook.pytest_runtest_protocol(item=item, nextitem=nextitem)
  File "c:\users\1111111\appdata\local\programs\python\python36\lib\site-packages\pluggy\hooks.py", line 286, in __call__
    return self._hookexec(self, self.get_hookimpls(), kwargs)
  File "c:\users\1111111\appdata\local\programs\python\python36\lib\site-packages\pluggy\manager.py", line 93, in _hookexec
    return self._inner_hookexec(hook, methods, kwargs)
  File "c:\users\1111111\appdata\local\programs\python\python36\lib\site-packages\pluggy\manager.py", line 87, in <lambda>
    firstresult=hook.spec.opts.get("firstresult") if hook.spec else False,
  File "c:\users\1111111\appdata\local\programs\python\python36\lib\site-packages\pluggy\callers.py", line 187, in _multicall
    res = hook_impl.function(*args)
  File "c:\users\1111111\appdata\local\programs\python\python36\lib\site-packages\_pytest\runner.py", line 109, in pytest_runtest_protocol
    runtestprotocol(item, nextitem=nextitem)
  File "c:\users\1111111\appdata\local\programs\python\python36\lib\site-packages\_pytest\runner.py", line 126, in runtestprotocol
    reports.append(call_and_report(item, "call", log))
  File "c:\users\1111111\appdata\local\programs\python\python36\lib\site-packages\_pytest\runner.py", line 215, in call_and_report
    call = call_runtest_hook(item, when, **kwds)
  File "c:\users\1111111\appdata\local\programs\python\python36\lib\site-packages\_pytest\runner.py", line 255, in call_runtest_hook
    lambda: ihook(item=item, **kwds), when=when, reraise=reraise
  File "c:\users\1111111\appdata\local\programs\python\python36\lib\site-packages\_pytest\runner.py", line 311, in from_call
    result: Optional[TResult] = func()
  File "c:\users\1111111\appdata\local\programs\python\python36\lib\site-packages\_pytest\runner.py", line 255, in <lambda>
    lambda: ihook(item=item, **kwds), when=when, reraise=reraise
  File "c:\users\1111111\appdata\local\programs\python\python36\lib\site-packages\pluggy\hooks.py", line 286, in __call__
    return self._hookexec(self, self.get_hookimpls(), kwargs)
  File "c:\users\1111111\appdata\local\programs\python\python36\lib\site-packages\pluggy\manager.py", line 93, in _hookexec
    return self._inner_hookexec(hook, methods, kwargs)
  File "c:\users\1111111\appdata\local\programs\python\python36\lib\site-packages\pluggy\manager.py", line 87, in <lambda>
    firstresult=hook.spec.opts.get("firstresult") if hook.spec else False,
  File "c:\users\1111111\appdata\local\programs\python\python36\lib\site-packages\pluggy\callers.py", line 187, in _multicall
    res = hook_impl.function(*args)
  File "c:\users\1111111\appdata\local\programs\python\python36\lib\site-packages\_pytest\runner.py", line 162, in pytest_runtest_call
    item.runtest()
  File "c:\users\1111111\appdata\local\programs\python\python36\lib\site-packages\_pytest\python.py", line 1641, in runtest
    self.ihook.pytest_pyfunc_call(pyfuncitem=self)
  File "c:\users\1111111\appdata\local\programs\python\python36\lib\site-packages\pluggy\hooks.py", line 286, in __call__
    return self._hookexec(self, self.get_hookimpls(), kwargs)
  File "c:\users\1111111\appdata\local\programs\python\python36\lib\site-packages\pluggy\manager.py", line 93, in _hookexec
    return self._inner_hookexec(hook, methods, kwargs)
  File "c:\users\1111111\appdata\local\programs\python\python36\lib\site-packages\pluggy\manager.py", line 87, in <lambda>
    firstresult=hook.spec.opts.get("firstresult") if hook.spec else False,
  File "c:\users\1111111\appdata\local\programs\python\python36\lib\site-packages\pluggy\callers.py", line 187, in _multicall
    res = hook_impl.function(*args)
  File "c:\users\1111111\appdata\local\programs\python\python36\lib\site-packages\_pytest\python.py", line 183, in pytest_pyfunc_call
    result = testfunction(**testargs)
  File "C:\Users\1111111\PycharmProjects\ApiAutoTest\script\test_login.py", line 65, in test_correct_login
    logging.info(e)
Message: AssertionError("没有登录进去\nassert 'QQ邮箱' == '登录QQ邮箱'\n  - 登录QQ邮箱\n  ? --\n  + QQ邮箱",)
Arguments: ()
